<?xml version="1.0" encoding="UTF-8"?>
<!-- Generated by org.testng.reporters.JUnitReportReporter -->
<testsuite hostname="DESKTOP-OU80H79" failures="2" tests="22" name="com.app.testng.FailedTestCases2" time="0.082" errors="0" timestamp="27 Jul 2022 01:05:55 GMT" skipped="20">
  <testcase classname="com.app.testng.FailedTestCases2" name="username" time="0.000">
    <skipped/>
  </testcase> <!-- username -->
  <testcase classname="com.app.testng.FailedTestCases2" name="username" time="0.001">
    <skipped/>
  </testcase> <!-- username -->
  <testcase classname="com.app.testng.FailedTestCases2" name="password" time="0.004">
    <skipped/>
  </testcase> <!-- password -->
  <testcase classname="com.app.testng.FailedTestCases2" name="password" time="0.001">
    <failure message="expected [true] but found [false]" type="java.lang.AssertionError">
      <![CDATA[java.lang.AssertionError: expected [true] but found [false]
at org.testng.Assert.fail(Assert.java:96)
at org.testng.Assert.failNotEquals(Assert.java:776)
at org.testng.Assert.assertTrue(Assert.java:44)
at org.testng.Assert.assertTrue(Assert.java:54)
at com.app.testng.FailedTestCases2.password(FailedTestCases2.java:17)
at java.base/jdk.internal.reflect.NativeMethodAccessorImpl.invoke0(Native Method)
at java.base/jdk.internal.reflect.NativeMethodAccessorImpl.invoke(NativeMethodAccessorImpl.java:62)
at java.base/jdk.internal.reflect.DelegatingMethodAccessorImpl.invoke(DelegatingMethodAccessorImpl.java:43)
at java.base/java.lang.reflect.Method.invoke(Method.java:566)
at org.testng.internal.MethodInvocationHelper.invokeMethod(MethodInvocationHelper.java:124)
at org.testng.internal.Invoker.invokeMethod(Invoker.java:583)
at org.testng.internal.Invoker.retryFailed(Invoker.java:839)
at org.testng.internal.Invoker.invokeTestMethods(Invoker.java:1010)
at org.testng.internal.TestMethodWorker.invokeTestMethods(TestMethodWorker.java:125)
at org.testng.internal.TestMethodWorker.run(TestMethodWorker.java:109)
at org.testng.TestRunner.privateRun(TestRunner.java:648)
at org.testng.TestRunner.run(TestRunner.java:505)
at org.testng.SuiteRunner.runTest(SuiteRunner.java:455)
at org.testng.SuiteRunner.runSequentially(SuiteRunner.java:450)
at org.testng.SuiteRunner.privateRun(SuiteRunner.java:415)
at org.testng.SuiteRunner.run(SuiteRunner.java:364)
at org.testng.SuiteRunnerWorker.runSuite(SuiteRunnerWorker.java:52)
at org.testng.SuiteRunnerWorker.run(SuiteRunnerWorker.java:84)
at org.testng.TestNG.runSuitesSequentially(TestNG.java:1208)
at org.testng.TestNG.runSuitesLocally(TestNG.java:1137)
at org.testng.TestNG.runSuites(TestNG.java:1049)
at org.testng.TestNG.run(TestNG.java:1017)
at org.testng.remote.AbstractRemoteTestNG.run(AbstractRemoteTestNG.java:115)
at org.testng.remote.RemoteTestNG.initAndRun(RemoteTestNG.java:251)
at org.testng.remote.RemoteTestNG.main(RemoteTestNG.java:77)
]]>
    </failure>
  </testcase> <!-- password -->
  <testcase classname="com.app.testng.FailedTestCases2" name="password" time="0.001">
    <skipped/>
  </testcase> <!-- password -->
  <testcase classname="com.app.testng.FailedTestCases2" name="username" time="0.001">
    <skipped/>
  </testcase> <!-- username -->
  <testcase classname="com.app.testng.FailedTestCases2" name="password" time="0.003">
    <skipped/>
  </testcase> <!-- password -->
  <testcase classname="com.app.testng.FailedTestCases2" name="password" time="0.003">
    <skipped/>
  </testcase> <!-- password -->
  <testcase classname="com.app.testng.FailedTestCases2" name="username" time="0.007">
    <skipped/>
  </testcase> <!-- username -->
  <testcase classname="com.app.testng.FailedTestCases2" name="password" time="0.003">
    <skipped/>
  </testcase> <!-- password -->
  <testcase classname="com.app.testng.FailedTestCases2" name="username" time="0.010">
    <skipped/>
  </testcase> <!-- username -->
  <testcase classname="com.app.testng.FailedTestCases2" name="username" time="0.004">
    <skipped/>
  </testcase> <!-- username -->
  <testcase classname="com.app.testng.FailedTestCases2" name="password" time="0.002">
    <skipped/>
  </testcase> <!-- password -->
  <testcase classname="com.app.testng.FailedTestCases2" name="username" time="0.002">
    <skipped/>
  </testcase> <!-- username -->
  <testcase classname="com.app.testng.FailedTestCases2" name="username" time="0.001">
    <failure message="expected [a] but found [A]" type="java.lang.AssertionError">
      <![CDATA[java.lang.AssertionError: expected [a] but found [A]
at org.testng.Assert.fail(Assert.java:96)
at org.testng.Assert.failNotEquals(Assert.java:776)
at org.testng.Assert.assertEqualsImpl(Assert.java:137)
at org.testng.Assert.assertEquals(Assert.java:118)
at org.testng.Assert.assertEquals(Assert.java:453)
at org.testng.Assert.assertEquals(Assert.java:463)
at com.app.testng.FailedTestCases2.username(FailedTestCases2.java:10)
at java.base/jdk.internal.reflect.NativeMethodAccessorImpl.invoke0(Native Method)
at java.base/jdk.internal.reflect.NativeMethodAccessorImpl.invoke(NativeMethodAccessorImpl.java:62)
at java.base/jdk.internal.reflect.DelegatingMethodAccessorImpl.invoke(DelegatingMethodAccessorImpl.java:43)
at java.base/java.lang.reflect.Method.invoke(Method.java:566)
at org.testng.internal.MethodInvocationHelper.invokeMethod(MethodInvocationHelper.java:124)
at org.testng.internal.Invoker.invokeMethod(Invoker.java:583)
at org.testng.internal.Invoker.retryFailed(Invoker.java:839)
at org.testng.internal.Invoker.invokeTestMethods(Invoker.java:1010)
at org.testng.internal.TestMethodWorker.invokeTestMethods(TestMethodWorker.java:125)
at org.testng.internal.TestMethodWorker.run(TestMethodWorker.java:109)
at org.testng.TestRunner.privateRun(TestRunner.java:648)
at org.testng.TestRunner.run(TestRunner.java:505)
at org.testng.SuiteRunner.runTest(SuiteRunner.java:455)
at org.testng.SuiteRunner.runSequentially(SuiteRunner.java:450)
at org.testng.SuiteRunner.privateRun(SuiteRunner.java:415)
at org.testng.SuiteRunner.run(SuiteRunner.java:364)
at org.testng.SuiteRunnerWorker.runSuite(SuiteRunnerWorker.java:52)
at org.testng.SuiteRunnerWorker.run(SuiteRunnerWorker.java:84)
at org.testng.TestNG.runSuitesSequentially(TestNG.java:1208)
at org.testng.TestNG.runSuitesLocally(TestNG.java:1137)
at org.testng.TestNG.runSuites(TestNG.java:1049)
at org.testng.TestNG.run(TestNG.java:1017)
at org.testng.remote.AbstractRemoteTestNG.run(AbstractRemoteTestNG.java:115)
at org.testng.remote.RemoteTestNG.initAndRun(RemoteTestNG.java:251)
at org.testng.remote.RemoteTestNG.main(RemoteTestNG.java:77)
]]>
    </failure>
  </testcase> <!-- username -->
  <testcase classname="com.app.testng.FailedTestCases2" name="password" time="0.022">
    <skipped/>
  </testcase> <!-- password -->
  <testcase classname="com.app.testng.FailedTestCases2" name="password" time="0.002">
    <skipped/>
  </testcase> <!-- password -->
  <testcase classname="com.app.testng.FailedTestCases2" name="username" time="0.002">
    <skipped/>
  </testcase> <!-- username -->
  <testcase classname="com.app.testng.FailedTestCases2" name="password" time="0.002">
    <skipped/>
  </testcase> <!-- password -->
  <testcase classname="com.app.testng.FailedTestCases2" name="username" time="0.002">
    <skipped/>
  </testcase> <!-- username -->
  <testcase classname="com.app.testng.FailedTestCases2" name="username" time="0.004">
    <skipped/>
  </testcase> <!-- username -->
  <testcase classname="com.app.testng.FailedTestCases2" name="password" time="0.005">
    <skipped/>
  </testcase> <!-- password -->
</testsuite> <!-- com.app.testng.FailedTestCases2 -->
